<?xml version='1.0' encoding='utf-8'?>
<robot xmlns:xacro="http://www.ros.org/wiki/xacro" name="fra333_lab2_20_1">



<material name="Dblue">
  <color rgba="${49/255} ${47/255} ${83/255} 1.0"/>
</material>

<material name="pink">
  <color rgba="${255/255} ${13/255} ${145/255} 1.0"/>
</material>

<material name="Blue">
  <color rgba="${85/255} ${51/255} ${255/255} 1.0"/>      
</material>

<link name="base_link"/>

<joint name="base_joint" type="fixed">
  <parent link="base_link"/>
  <child link="link_0"/>
</joint>

<link name="link_0">
    <visual>
      <origin rpy="0 0 0" xyz="0 0 0"/>
      <geometry>
        <mesh filename="package://robot20_description/meshes/link_0.STL"/>
      </geometry>
      <material name="Dblue"/>
    </visual>
  </link>

  <joint name="joint_1" type="revolute">
    <parent link="link_0"/>
    <child link="link_1"/>
    <origin rpy="0 0 0" xyz="0 0 0.01"/>
    <axis xyz="0 0 1"/>
    <limit lower="-3.14" upper="3.14" effort="0.5" velocity="0.5"/>
  </joint>

  <link name="link_1">
    <visual>
      <origin rpy="0 0 3.14 " xyz="0 0 0"/>
      <geometry>
        <mesh filename="package://robot20_description/meshes/link_1.STL"/>
      </geometry>
      <material name="Blue"/>
    </visual>
  </link>

  <joint name="joint_2" type="revolute">
    <parent link="link_1"/>
    <child link="link_2"/>
    <origin rpy="1.57079632679   0 0" xyz="0.040 0 0.125"/>
    <axis xyz="0 0 1"/>
    <limit lower="-3.14" upper="3.14" effort="0.5" velocity="0.5"/>
  </joint>

  <link name="link_2">
    <visual>
      <origin rpy="0 0 0" xyz="0 0 0"/>
      <geometry>
        <mesh filename="package://robot20_description/meshes/link_2.STL"/>
      </geometry>
      <material name="pink"/>
    </visual>
  </link>

  <joint name="joint_3" type="revolute">
    <parent link="link_2"/>
    <child link="link_3"/>
    <origin rpy="0 0 0" xyz="0.15 0 0"/>
    <axis xyz="0 0 1"/>
    <limit lower="-3.14" upper="3.14" effort="0.5" velocity="0.5"/>
  </joint>

  <link name="link_3">
    <visual>
      <origin rpy="0 0 0" xyz="0 0 0"/>
      <geometry>
        <mesh filename="package://robot20_description/meshes/link_3.STL"/>
      </geometry>
      <material name="pink"/>
    </visual>
  </link>

  <joint name="joint_eff" type="fixed">
    <parent link="link_3"/>
    <child link="end_effector"/>
    <origin rpy="1.57 0 1.57" xyz="0.050 0 0"/>
    <axis xyz="0 0 1"/>
  </joint>

  <link name="end_effector">
  </link>

</robot>
