<?xml version="1.0"?>
<robot xmlns:xacro="http://www.ros.org/wiki/xacro"  name="robot">

    <!-- This is an example of a URDF. -->
    <!-- As we move through the file, new things to note will be pointed out. -->
    <!-- It's not meant an example of GOOD design, but an example of some of the various features of URDF/xacro. -->



    <!-- This will include all the contents of example_include.xacro first. Go check it out! -->
    <xacro:include filename="example_include.xacro" />



    <!-- This first link called "world" is empty -->
    <link name="world"></link>


    <!-- A simple fixed joint from our empty world link, to our base. -->
    <!-- The base origin is offset from the world origin. -->
    <joint name="base_joint" type="fixed">
        <origin xyz="0 0 0" rpy="0 0 0"/>
        <parent link="world"/>
        <child link="link_0"/>        
    </joint>


    <!-- base_link is a large rectangular plate. Some things to note: -->
    <!-- - We set the visual origin Z to half the box height, so that the link origin sits at the bottom of the box -->
    <!-- - We set the collision to be identical to the visual -->
    <!-- - We specified the colour manually (but still need to enter a name) -->
    <!-- - We specified all the inertial parameters manually -->
    
    <link name="link_0">
        <visual>
            <origin xyz="0 0 0.0" rpy="0 0 0"/>
            <geometry>
                <!-- <box size="2.5 1.5 0.1" /> -->
                <mesh filename="file:///$(find lab4_robot_description)/meshes/link_0.stl"/>
            </geometry>
        </visual>
        <collision>
            <origin xyz="0 0 0.0" rpy="0 0 0"/>
            <contact_coefficients mu="0" kp="1000.0" kd="1.0"/>
            <geometry>
                <mesh filename="file:///$(find lab4_robot_description)/meshes/link_0.stl"/>
                <!-- <box size="2.5 1.5 0.1" /> -->
            </geometry>
        </collision>
        <inertial>
            <origin xyz="0 0 .000914" rpy="0 0 0"/>
            <mass value="0.16486" />
            <inertia ixx="0.00015134507" ixy="0.0" ixz="0.0" iyy="0.00015134507" iyz="0.0" izz="0.00029194203" />
        </inertial>
    </link>

    <joint name="joint_0" type="fixed">
        <parent link="link_0"/>
        <child link="link_1"/>
        <origin rpy="0 0 0" xyz="0 0 0"/>
        <axis xyz="0 0 1"/>
        <dynamics damping="0" friction="0"/>
    </joint>

    <joint name="joint_1" type="revolute">
        <parent link="link_0"/>
        <child link="link_1"/>
        <origin rpy="0 0 0" xyz="0 0 0.135"/>
        <axis xyz="0 0 1"/>
        <limit lower="-3.14" upper="3.14" effort="0.5" velocity="0.5"/>
        <dynamics damping="0" friction="0"/>
    </joint>

    <link name="link_1">
        <visual>
            <origin rpy="0 0 3.14 " xyz="0 0 -0.125"/>
            <geometry>
                <!-- <box size="2.5 1.5 0.1" /> -->
                <mesh filename="file:///$(find lab4_robot_description)/meshes/link_1.stl"/>
            </geometry>
        </visual>
        <collision>
            <origin xyz="0 0 0.0" rpy="0 0 0"/>
            <contact_coefficients mu="0" kp="1000.0" kd="1.0"/>
            <geometry>
                <mesh filename="file:///$(find lab4_robot_description)/meshes/link_1.stl"/>
                <!-- <box size="0.01 0.01 0.01" /> -->
            </geometry>
        </collision>
        <inertial>
            <origin xyz="-0.00227 0 0.06038" rpy="0 0 0"/>
            <mass value="0.33244" />
            <inertia ixx="0.00050960520" ixy="0.0" ixz="-0.00004897127" iyy="0.00054096526" iyz="0.0" izz="0.00016177928" />
        </inertial>
    </link>

  <joint name="joint_2" type="revolute">
    <parent link="link_1"/>
    <child link="link_2"/>
    <origin rpy="1.57079632679   0 0" xyz="0.040 0 0"/>
    <axis xyz="0 0 1"/>
    <limit lower="-3.14" upper="3.14" effort="0.5" velocity="0.5"/>
    <dynamics damping="0" friction="0"/>
  </joint>

    <link name="link_2">
        <visual>
            <origin xyz="0 0 0.0" rpy="0 0 0"/>
            <geometry>
                <!-- <box size="2.5 1.5 0.1" /> -->
                <mesh filename="file:///$(find lab4_robot_description)/meshes/link_2.stl"/>
            </geometry>
        </visual>
        <collision>
            <contact_coefficients mu="0" kp="1000.0" kd="1.0"/>
            <origin xyz="0 0 0.0" rpy="0 0 0"/>
            <geometry>
                <!-- <box size="0.01 0.01 0.01" /> -->
                <mesh filename="file:///$(find lab4_robot_description)/meshes/link_2.stl"/>
                <!-- <box size="2.5 1.5 0.1" /> -->
            </geometry>
        </collision>
        <inertial>
            <origin xyz="0.07867 0 0.0" rpy="0 0 0"/>
            <mass value="0.35295" />
            <inertia ixx="0.000142422.27" ixy="0.0" ixz="0.0" iyy="0.00069087368" iyz="0.0" izz="0.00069536540" />
        </inertial>
    </link>

    <joint name="joint_3" type="revolute">
        <parent link="link_2"/>
        <child link="link_3"/>
        <origin rpy="0 0 0" xyz="0.15 0 0"/>
        <axis xyz="0 0 1"/>
        <limit lower="-3.14" upper="3.14" effort="0.5" velocity="0.5"/>
        <dynamics damping="0" friction="0"/>
      </joint>

    <link name="link_3">
        <visual>
            <origin xyz="0 0 0.0" rpy="0 0 0"/>
            <geometry>
                <mesh filename="file:///$(find lab4_robot_description)/meshes/link_3.stl"/>
            </geometry>
        </visual>
        <collision>
            <contact_coefficients mu="0" kp="1000.0" kd="1.0"/>
            <origin xyz="0 0 0.0" rpy="0 0 0"/>
            <geometry>
                <mesh filename="file:///$(find lab4_robot_description)/meshes/link_3.stl"/>
            </geometry>
        </collision>
        <inertial>
            <origin xyz="0.04574 0 0.0" rpy="0 0 0"/>
            <mass value="0.19651" />
            <inertia ixx="0.00013273263" ixy="0.0" ixz="0.0" iyy="0.30209633" iyz="0.0" izz="0.00027662369" />
        </inertial>
    </link>

  <joint name="joint_eff" type="fixed">
    <parent link="link_3"/>
    <child link="end_effector"/>
    <origin rpy="1.57 0 1.57" xyz="0.12 0 0"/>
    <axis xyz="0 0 1"/>
    
  </joint>
    
    <link name="end_effector"/>


    <xacro:include filename="example_gazebo.xacro" />


</robot>